Workbook

Sheet INVENTAIRE
A1: ID_Materiel | B1: Catégorie | C1: Désignation | D1: Localisation | E1: Stock_Initial | F1: Entrées | G1: Sorties | H1: Stock_Actuel | I1: Stock_Min | J1: Alerte | K1: Statut | L1: Numéros_de_série | M1: Détails
A2: IT-122-0001 | C2: Box Otrum | D2: 122 | E2: 0 | F2: =IFERROR(SUMIFS(MOUVEMENTS_STOCK!$E:$E,MOUVEMENTS_STOCK!$C:$C,A2,MOUVEMENTS_STOCK!$D:$D,"ENTREE"),0) -> 1 | G2: =IFERROR(SUMIFS(MOUVEMENTS_STOCK!$E:$E,MOUVEMENTS_STOCK!$C:$C,A2,MOUVEMENTS_STOCK!$D:$D,"SORTIE"),0) -> 0 | H2: =E2+F2-G2 -> 1 | I2: 1 | J2: =IF(H2<=I2,"CRITIQUE",IF(H2<=I2+1,"BAS","OK")) -> CRITIQUE | K2: =IF(J2="CRITIQUE","A_REAPPROVISIONNER",IF(J2="BAS","SURVEILLER","OK")) -> A_REAPPROVISIONNER | M2: Old otrum box
A3: IT-122-0002 | C3: Clavier | D3: 122 | E3: 0 | F3: =IFERROR(SUMIFS(MOUVEMENTS_STOCK!$E:$E,MOUVEMENTS_STOCK!$C:$C,A3,MOUVEMENTS_STOCK!$D:$D,"ENTREE"),0) -> 0 | G3: =IFERROR(SUMIFS(MOUVEMENTS_STOCK!$E:$E,MOUVEMENTS_STOCK!$C:$C,A3,MOUVEMENTS_STOCK!$D:$D,"SORTIE"),0) -> 0 | H3: =E3+F3-G3 -> 0 | I3: 1 | J3: =IF(H3<=I3,"CRITIQUE",IF(H3<=I3+1,"BAS","OK")) -> CRITIQUE | K3: =IF(J3="CRITIQUE","A_REAPPROVISIONNER",IF(J3="BAS","SURVEILLER","OK")) -> A_REAPPROVISIONNER
A4: IT-122-0003 | C4: Compteuse | D4: 122 | E4: 2 | F4: =IFERROR(SUMIFS(MOUVEMENTS_STOCK!$E:$E,MOUVEMENTS_STOCK!$C:$C,A4,MOUVEMENTS_STOCK!$D:$D,"ENTREE"),0) -> 0 | G4: =IFERROR(SUMIFS(MOUVEMENTS_STOCK!$E:$E,MOUVEMENTS_STOCK!$C:$C,A4,MOUVEMENTS_STOCK!$D:$D,"SORTIE"),0) -> 0 | H4: =E4+F4-G4 -> 2 | I4: 2 | J4: =IF(H4<=I4,"CRITIQUE",IF(H4<=I4+1,"BAS","OK")) -> CRITIQUE | K4: =IF(J4="CRITIQUE","A_REAPPROVISIONNER",IF(J4="BAS","SURVEILLER","OK")) -> A_REAPPROVISIONNER
A5: IT-122-0004 | C5: Facture printer | D5: 122 | E5: 3 | F5: =IFERROR(SUMIFS(MOUVEMENTS_STOCK!$E:$E,MOUVEMENTS_STOCK!$C:$C,A5,MOUVEMENTS_STOCK!$D:$D,"ENTREE"),0) -> 0 | G5: =IFERROR(SUMIFS(MOUVEMENTS_STOCK!$E:$E,MOUVEMENTS_STOCK!$C:$C,A5,MOUVEMENTS_STOCK!$D:$D,"SORTIE"),0) -> 0 | H5: =E5+F5-G5 -> 3 | I5: 2 | J5: =IF(H5<=I5,"CRITIQUE",IF(H5<=I5+1,"BAS","OK")) -> BAS | K5: =IF(J5="CRITIQUE","A_REAPPROVISIONNER",IF(J5="BAS","SURVEILLER","OK")) -> SURVEILLER | M5: micros
A6: IT-122-0005 | C6: Imprimantes HP | D6: 122 | E6: 16 | F6: =IFERROR(SUMIFS(MOUVEMENTS_STOCK!$E:$E,MOUVEMENTS_STOCK!$C:$C,A6,MOUVEMENTS_STOCK!$D:$D,"ENTREE"),0) -> 0 | G6: =IFERROR(SUMIFS(MOUVEMENTS_STOCK!$E:$E,MOUVEMENTS_STOCK!$C:$C,A6,MOUVEMENTS_STOCK!$D:$D,"SORTIE"),0) -> 0 | H6: =E6+F6-G6 -> 16 | I6: 2 | J6: =IF(H6<=I6,"CRITIQUE",IF(H6<=I6+1,"BAS","OK")) -> OK | K6: =IF(J6="CRITIQUE","A_REAPPROVISIONNER",IF(J6="BAS","SURVEILLER","OK")) -> OK | M6: Officejet
A7: IT-122-0006 | C7: Mixte Cables | D7: 122 | E7: 0 | F7: =IFERROR(SUMIFS(MOUVEMENTS_STOCK!$E:$E,MOUVEMENTS_STOCK!$C:$C,A7,MOUVEMENTS_STOCK!$D:$D,"ENTREE"),0) -> 0 | G7: =IFERROR(SUMIFS(MOUVEMENTS_STOCK!$E:$E,MOUVEMENTS_STOCK!$C:$C,A7,MOUVEMENTS_STOCK!$D:$D,"SORTIE"),0) -> 0 | H7: =E7+F7-G7 -> 0 | I7: 1 | J7: =IF(H7<=I7,"CRITIQUE",IF(H7<=I7+1,"BAS","OK")) -> CRITIQUE | K7: =IF(J7="CRITIQUE","A_REAPPROVISIONNER",IF(J7="BAS","SURVEILLER","OK")) -> A_REAPPROVISIONNER | L7: N/A | M7: hdmi, Vga, display, power…
A8: IT-122-0007 | C8: Moniteurs HDMI | D8: 122 | E8: 4 | F8: =IFERROR(SUMIFS(MOUVEMENTS_STOCK!$E:$E,MOUVEMENTS_STOCK!$C:$C,A8,MOUVEMENTS_STOCK!$D:$D,"ENTREE"),0) -> 0 | G8: =IFERROR(SUMIFS(MOUVEMENTS_STOCK!$E:$E,MOUVEMENTS_STOCK!$C:$C,A8,MOUVEMENTS_STOCK!$D:$D,"SORTIE"),0) -> 0 | H8: =E8+F8-G8 -> 4 | I8: 2 | J8: =IF(H8<=I8,"CRITIQUE",IF(H8<=I8+1,"BAS","OK")) -> OK | K8: =IF(J8="CRITIQUE","A_REAPPROVISIONNER",IF(J8="BAS","SURVEILLER","OK")) -> OK | M8: New monitor serie
A9: IT-122-0008 | C9: PC | D9: 122 | E9: 11 | F9: =IFERROR(SUMIFS(MOUVEMENTS_STOCK!$E:$E,MOUVEMENTS_STOCK!$C:$C,A9,MOUVEMENTS_STOCK!$D:$D,"ENTREE"),0) -> 0 | G9: =IFERROR(SUMIFS(MOUVEMENTS_STOCK!$E:$E,MOUVEMENTS_STOCK!$C:$C,A9,MOUVEMENTS_STOCK!$D:$D,"SORTIE"),0) -> 0 | H9: =E9+F9-G9 -> 11 | I9: 2 | J9: =IF(H9<=I9,"CRITIQUE",IF(H9<=I9+1,"BAS","OK")) -> OK | K9: =IF(J9="CRITIQUE","A_REAPPROVISIONNER",IF(J9="BAS","SURVEILLER","OK")) -> OK | M9: Desktop HP
A10: IT-122-0009 | C10: POS | D10: 122 | E10: 6 | F10: =IFERROR(SUMIFS(MOUVEMENTS_STOCK!$E:$E,MOUVEMENTS_STOCK!$C:$C,A10,MOUVEMENTS_STOCK!$D:$D,"ENTREE"),0) -> 0 | G10: =IFERROR(SUMIFS(MOUVEMENTS_STOCK!$E:$E,MOUVEMENTS_STOCK!$C:$C,A10,MOUVEMENTS_STOCK!$D:$D,"SORTIE"),0) -> 0 | H10: =E10+F10-G10 -> 6 | I10: 2 | J10: =IF(H10<=I10,"CRITIQUE",IF(H10<=I10+1,"BAS","OK")) -> OK | K10: =IF(J10="CRITIQUE","A_REAPPROVISIONNER",IF(J10="BAS","SURVEILLER","OK")) -> OK | M10: MICROS
A11: IT-122-0010 | C11: Serveurs | D11: 122 | E11: 2 | F11: =IFERROR(SUMIFS(MOUVEMENTS_STOCK!$E:$E,MOUVEMENTS_STOCK!$C:$C,A11,MOUVEMENTS_STOCK!$D:$D,"ENTREE"),0) -> 0 | G11: =IFERROR(SUMIFS(MOUVEMENTS_STOCK!$E:$E,MOUVEMENTS_STOCK!$C:$C,A11,MOUVEMENTS_STOCK!$D:$D,"SORTIE"),0) -> 0 | H11: =E11+F11-G11 -> 2 | I11: 2 | J11: =IF(H11<=I11,"CRITIQUE",IF(H11<=I11+1,"BAS","OK")) -> CRITIQUE | K11: =IF(J11="CRITIQUE","A_REAPPROVISIONNER",IF(J11="BAS","SURVEILLER","OK")) -> A_REAPPROVISIONNER | M11: HP
A12: IT-122-0011 | C12: Téléphone | D12: 122 | E12: 0 | F12: =IFERROR(SUMIFS(MOUVEMENTS_STOCK!$E:$E,MOUVEMENTS_STOCK!$C:$C,A12,MOUVEMENTS_STOCK!$D:$D,"ENTREE"),0) -> 0 | G12: =IFERROR(SUMIFS(MOUVEMENTS_STOCK!$E:$E,MOUVEMENTS_STOCK!$C:$C,A12,MOUVEMENTS_STOCK!$D:$D,"SORTIE"),0) -> 0 | H12: =E12+F12-G12 -> 0 | I12: 1 | J12: =IF(H12<=I12,"CRITIQUE",IF(H12<=I12+1,"BAS","OK")) -> CRITIQUE | K12: =IF(J12="CRITIQUE","A_REAPPROVISIONNER",IF(J12="BAS","SURVEILLER","OK")) -> A_REAPPROVISIONNER | M12: Old téléphone
A13: IT-133-0012 | C13: Autres | D13: 133 | E13: 0 | F13: =IFERROR(SUMIFS(MOUVEMENTS_STOCK!$E:$E,MOUVEMENTS_STOCK!$C:$C,A13,MOUVEMENTS_STOCK!$D:$D,"ENTREE"),0) -> 0 | G13: =IFERROR(SUMIFS(MOUVEMENTS_STOCK!$E:$E,MOUVEMENTS_STOCK!$C:$C,A13,MOUVEMENTS_STOCK!$D:$D,"SORTIE"),0) -> 0 | H13: =E13+F13-G13 -> 0 | I13: 1 | J13: =IF(H13<=I13,"CRITIQUE",IF(H13<=I13+1,"BAS","OK")) -> CRITIQUE | K13: =IF(J13="CRITIQUE","A_REAPPROVISIONNER",IF(J13="BAS","SURVEILLER","OK")) -> A_REAPPROVISIONNER
A14: IT-133-0013 | C14: Autres Switch | D14: 133 | E14: 6 | F14: =IFERROR(SUMIFS(MOUVEMENTS_STOCK!$E:$E,MOUVEMENTS_STOCK!$C:$C,A14,MOUVEMENTS_STOCK!$D:$D,"ENTREE"),0) -> 0 | G14: =IFERROR(SUMIFS(MOUVEMENTS_STOCK!$E:$E,MOUVEMENTS_STOCK!$C:$C,A14,MOUVEMENTS_STOCK!$D:$D,"SORTIE"),0) -> 0 | H14: =E14+F14-G14 -> 6 | I14: 2 | J14: =IF(H14<=I14,"CRITIQUE",IF(H14<=I14+1,"BAS","OK")) -> OK | K14: =IF(J14="CRITIQUE","A_REAPPROVISIONNER",IF(J14="BAS","SURVEILLER","OK")) -> OK | L14: SG252IQ0KQ_J9146A | M14: HP 2910al-24G;PoE
A15: IT-133-0014 | C15: Box Otrum | D15: 122 | E15: 10 | F15: =IFERROR(SUMIFS(MOUVEMENTS_STOCK!$E:$E,MOUVEMENTS_STOCK!$C:$C,A15,MOUVEMENTS_STOCK!$D:$D,"ENTREE"),0) -> 0 | G15: =IFERROR(SUMIFS(MOUVEMENTS_STOCK!$E:$E,MOUVEMENTS_STOCK!$C:$C,A15,MOUVEMENTS_STOCK!$D:$D,"SORTIE"),0) -> 0 | H15: =E15+F15-G15 -> 10 | I15: 2 | J15: =IF(H15<=I15,"CRITIQUE",IF(H15<=I15+1,"BAS","OK")) -> OK | K15: =IF(J15="CRITIQUE","A_REAPPROVISIONNER",IF(J15="BAS","SURVEILLER","OK")) -> OK | L15: N/A | M15: Old box system
A16: IT-133-0015 | C16: Cables | D16: 133 | E16: 0 | F16: =IFERROR(SUMIFS(MOUVEMENTS_STOCK!$E:$E,MOUVEMENTS_STOCK!$C:$C,A16,MOUVEMENTS_STOCK!$D:$D,"ENTREE"),0) -> 0 | G16: =IFERROR(SUMIFS(MOUVEMENTS_STOCK!$E:$E,MOUVEMENTS_STOCK!$C:$C,A16,MOUVEMENTS_STOCK!$D:$D,"SORTIE"),0) -> 0 | H16: =E16+F16-G16 -> 0 | I16: 1 | J16: =IF(H16<=I16,"CRITIQUE",IF(H16<=I16+1,"BAS","OK")) -> CRITIQUE | K16: =IF(J16="CRITIQUE","A_REAPPROVISIONNER",IF(J16="BAS","SURVEILLER","OK")) -> A_REAPPROVISIONNER
A17: IT-133-0016 | C17: Clavier | D17: 133 | E17: 20 | F17: =IFERROR(SUMIFS(MOUVEMENTS_STOCK!$E:$E,MOUVEMENTS_STOCK!$C:$C,A17,MOUVEMENTS_STOCK!$D:$D,"ENTREE"),0) -> 0 | G17: =IFERROR(SUMIFS(MOUVEMENTS_STOCK!$E:$E,MOUVEMENTS_STOCK!$C:$C,A17,MOUVEMENTS_STOCK!$D:$D,"SORTIE"),0) -> 0 | H17: =E17+F17-G17 -> 20 | I17: 2 | J17: =IF(H17<=I17,"CRITIQUE",IF(H17<=I17+1,"BAS","OK")) -> OK | K17: =IF(J17="CRITIQUE","A_REAPPROVISIONNER",IF(J17="BAS","SURVEILLER","OK")) -> OK | L17: N/A | M17: Old
A18: IT-133-0017 | C18: Coffre fort | D18: 133 | E18: 0 | F18: =IFERROR(SUMIFS(MOUVEMENTS_STOCK!$E:$E,MOUVEMENTS_STOCK!$C:$C,A18,MOUVEMENTS_STOCK!$D:$D,"ENTREE"),0) -> 0 | G18: =IFERROR(SUMIFS(MOUVEMENTS_STOCK!$E:$E,MOUVEMENTS_STOCK!$C:$C,A18,MOUVEMENTS_STOCK!$D:$D,"SORTIE"),0) -> 0 | H18: =E18+F18-G18 -> 0 | I18: 1 | J18: =IF(H18<=I18,"CRITIQUE",IF(H18<=I18+1,"BAS","OK")) -> CRITIQUE | K18: =IF(J18="CRITIQUE","A_REAPPROVISIONNER",IF(J18="BAS","SURVEILLER","OK")) -> A_REAPPROVISIONNER
A19: IT-133-0018 | C19: Ecran HDMI | D19: 133 | E19: 2 | F19: =IFERROR(SUMIFS(MOUVEMENTS_STOCK!$E:$E,MOUVEMENTS_STOCK!$C:$C,A19,MOUVEMENTS_STOCK!$D:$D,"ENTREE"),0) -> 0 | G19: =IFERROR(SUMIFS(MOUVEMENTS_STOCK!$E:$E,MOUVEMENTS_STOCK!$C:$C,A19,MOUVEMENTS_STOCK!$D:$D,"SORTIE"),0) -> 0 | H19: =E19+F19-G19 -> 2 | I19: 2 | J19: =IF(H19<=I19,"CRITIQUE",IF(H19<=I19+1,"BAS","OK")) -> CRITIQUE | K19: =IF(J19="CRITIQUE","A_REAPPROVISIONNER",IF(J19="BAS","SURVEILLER","OK")) -> A_REAPPROVISIONNER
A20: IT-133-0019 | C20: HDMI | D20: 133 | E20: 0 | F20: =IFERROR(SUMIFS(MOUVEMENTS_STOCK!$E:$E,MOUVEMENTS_STOCK!$C:$C,A20,MOUVEMENTS_STOCK!$D:$D,"ENTREE"),0) -> 0 | G20: =IFERROR(SUMIFS(MOUVEMENTS_STOCK!$E:$E,MOUVEMENTS_STOCK!$C:$C,A20,MOUVEMENTS_STOCK!$D:$D,"SORTIE"),0) -> 0 | H20: =E20+F20-G20 -> 0 | I20: 1 | J20: =IF(H20<=I20,"CRITIQUE",IF(H20<=I20+1,"BAS","OK")) -> CRITIQUE | K20: =IF(J20="CRITIQUE","A_REAPPROVISIONNER",IF(J20="BAS","SURVEILLER","OK")) -> A_REAPPROVISIONNER | L20: N/A | M20: Court 2 à 3 mètres
A21: IT-133-0020 | C21: HP 280 G2 | D21: 133 | E21: 4 | F21: =IFERROR(SUMIFS(MOUVEMENTS_STOCK!$E:$E,MOUVEMENTS_STOCK!$C:$C,A21,MOUVEMENTS_STOCK!$D:$D,"ENTREE"),0) -> 0 | G21: =IFERROR(SUMIFS(MOUVEMENTS_STOCK!$E:$E,MOUVEMENTS_STOCK!$C:$C,A21,MOUVEMENTS_STOCK!$D:$D,"SORTIE"),0) -> 0 | H21: =E21+F21-G21 -> 4 | I21: 2 | J21: =IF(H21<=I21,"CRITIQUE",IF(H21<=I21+1,"BAS","OK")) -> OK | K21: =IF(J21="CRITIQUE","A_REAPPROVISIONNER",IF(J21="BAS","SURVEILLER","OK")) -> OK
A22: IT-133-0021 | C22: HP Compaq | D22: 133 | E22: 33 | F22: =IFERROR(SUMIFS(MOUVEMENTS_STOCK!$E:$E,MOUVEMENTS_STOCK!$C:$C,A22,MOUVEMENTS_STOCK!$D:$D,"ENTREE"),0) -> 0 | G22: =IFERROR(SUMIFS(MOUVEMENTS_STOCK!$E:$E,MOUVEMENTS_STOCK!$C:$C,A22,MOUVEMENTS_STOCK!$D:$D,"SORTIE"),0) -> 0 | H22: =E22+F22-G22 -> 33 | I22: 2 | J22: =IF(H22<=I22,"CRITIQUE",IF(H22<=I22+1,"BAS","OK")) -> OK | K22: =IF(J22="CRITIQUE","A_REAPPROVISIONNER",IF(J22="BAS","SURVEILLER","OK")) -> OK
A23: IT-133-0022 | C23: HP Elite Desk | D23: 133 | E23: 1 | F23: =IFERROR(SUMIFS(MOUVEMENTS_STOCK!$E:$E,MOUVEMENTS_STOCK!$C:$C,A23,MOUVEMENTS_STOCK!$D:$D,"ENTREE"),0) -> 0 | G23: =IFERROR(SUMIFS(MOUVEMENTS_STOCK!$E:$E,MOUVEMENTS_STOCK!$C:$C,A23,MOUVEMENTS_STOCK!$D:$D,"SORTIE"),0) -> 0 | H23: =E23+F23-G23 -> 1 | I23: 1 | J23: =IF(H23<=I23,"CRITIQUE",IF(H23<=I23+1,"BAS","OK")) -> CRITIQUE | K23: =IF(J23="CRITIQUE","A_REAPPROVISIONNER",IF(J23="BAS","SURVEILLER","OK")) -> A_REAPPROVISIONNER
A24: IT-133-0023 | C24: HP Pro | D24: 133 | E24: 5 | F24: =IFERROR(SUMIFS(MOUVEMENTS_STOCK!$E:$E,MOUVEMENTS_STOCK!$C:$C,A24,MOUVEMENTS_STOCK!$D:$D,"ENTREE"),0) -> 0 | G24: =IFERROR(SUMIFS(MOUVEMENTS_STOCK!$E:$E,MOUVEMENTS_STOCK!$C:$C,A24,MOUVEMENTS_STOCK!$D:$D,"SORTIE"),0) -> 0 | H24: =E24+F24-G24 -> 5 | I24: 2 | J24: =IF(H24<=I24,"CRITIQUE",IF(H24<=I24+1,"BAS","OK")) -> OK | K24: =IF(J24="CRITIQUE","A_REAPPROVISIONNER",IF(J24="BAS","SURVEILLER","OK")) -> OK
A25: IT-133-0024 | C25: HP Prodesk | D25: 133 | E25: 1 | F25: =IFERROR(SUMIFS(MOUVEMENTS_STOCK!$E:$E,MOUVEMENTS_STOCK!$C:$C,A25,MOUVEMENTS_STOCK!$D:$D,"ENTREE"),0) -> 0 | G25: =IFERROR(SUMIFS(MOUVEMENTS_STOCK!$E:$E,MOUVEMENTS_STOCK!$C:$C,A25,MOUVEMENTS_STOCK!$D:$D,"SORTIE"),0) -> 0 | H25: =E25+F25-G25 -> 1 | I25: 1 | J25: =IF(H25<=I25,"CRITIQUE",IF(H25<=I25+1,"BAS","OK")) -> CRITIQUE | K25: =IF(J25="CRITIQUE","A_REAPPROVISIONNER",IF(J25="BAS","SURVEILLER","OK")) -> A_REAPPROVISIONNER
A26: IT-133-0025 | C26: Imprimante HP | D26: 133 | E26: 3 | F26: =IFERROR(SUMIFS(MOUVEMENTS_STOCK!$E:$E,MOUVEMENTS_STOCK!$C:$C,A26,MOUVEMENTS_STOCK!$D:$D,"ENTREE"),0) -> 0 | G26: =IFERROR(SUMIFS(MOUVEMENTS_STOCK!$E:$E,MOUVEMENTS_STOCK!$C:$C,A26,MOUVEMENTS_STOCK!$D:$D,"SORTIE"),0) -> 0 | H26: =E26+F26-G26 -> 3 | I26: 2 | J26: =IF(H26<=I26,"CRITIQUE",IF(H26<=I26+1,"BAS","OK")) -> BAS | K26: =IF(J26="CRITIQUE","A_REAPPROVISIONNER",IF(J26="BAS","SURVEILLER","OK")) -> SURVEILLER | M26: HP Officejet 8730; laserJet P3015; laserJet Pro MFP 130 fw
A27: IT-133-0026 | C27: Imprimantes | D27: 133 | E27: 0 | F27: =IFERROR(SUMIFS(MOUVEMENTS_STOCK!$E:$E,MOUVEMENTS_STOCK!$C:$C,A27,MOUVEMENTS_STOCK!$D:$D,"ENTREE"),0) -> 0 | G27: =IFERROR(SUMIFS(MOUVEMENTS_STOCK!$E:$E,MOUVEMENTS_STOCK!$C:$C,A27,MOUVEMENTS_STOCK!$D:$D,"SORTIE"),0) -> 0 | H27: =E27+F27-G27 -> 0 | I27: 1 | J27: =IF(H27<=I27,"CRITIQUE",IF(H27<=I27+1,"BAS","OK")) -> CRITIQUE | K27: =IF(J27="CRITIQUE","A_REAPPROVISIONNER",IF(J27="BAS","SURVEILLER","OK")) -> A_REAPPROVISIONNER
A28: IT-133-0027 | C28: Moniteurs | D28: 133 | E28: 21 | F28: =IFERROR(SUMIFS(MOUVEMENTS_STOCK!$E:$E,MOUVEMENTS_STOCK!$C:$C,A28,MOUVEMENTS_STOCK!$D:$D,"ENTREE"),0) -> 0 | G28: =IFERROR(SUMIFS(MOUVEMENTS_STOCK!$E:$E,MOUVEMENTS_STOCK!$C:$C,A28,MOUVEMENTS_STOCK!$D:$D,"SORTIE"),0) -> 0 | H28: =E28+F28-G28 -> 21 | I28: 2 | J28: =IF(H28<=I28,"CRITIQUE",IF(H28<=I28+1,"BAS","OK")) -> OK | K28: =IF(J28="CRITIQUE","A_REAPPROVISIONNER",IF(J28="BAS","SURVEILLER","OK")) -> OK | M28: moniteur type VGA (old); moniteur type hdmi (old)
A29: IT-133-0028 | C29: Piles 3V | D29: 133 | E29: 0 | F29: =IFERROR(SUMIFS(MOUVEMENTS_STOCK!$E:$E,MOUVEMENTS_STOCK!$C:$C,A29,MOUVEMENTS_STOCK!$D:$D,"ENTREE"),0) -> 0 | G29: =IFERROR(SUMIFS(MOUVEMENTS_STOCK!$E:$E,MOUVEMENTS_STOCK!$C:$C,A29,MOUVEMENTS_STOCK!$D:$D,"SORTIE"),0) -> 0 | H29: =E29+F29-G29 -> 0 | I29: 1 | J29: =IF(H29<=I29,"CRITIQUE",IF(H29<=I29+1,"BAS","OK")) -> CRITIQUE | K29: =IF(J29="CRITIQUE","A_REAPPROVISIONNER",IF(J29="BAS","SURVEILLER","OK")) -> A_REAPPROVISIONNER | L29: N/A | M29: Kodak Uktra Lithium
A30: IT-133-0029 | C30: Piles 9V | D30: 133 | E30: 4 | F30: =IFERROR(SUMIFS(MOUVEMENTS_STOCK!$E:$E,MOUVEMENTS_STOCK!$C:$C,A30,MOUVEMENTS_STOCK!$D:$D,"ENTREE"),0) -> 0 | G30: =IFERROR(SUMIFS(MOUVEMENTS_STOCK!$E:$E,MOUVEMENTS_STOCK!$C:$C,A30,MOUVEMENTS_STOCK!$D:$D,"SORTIE"),0) -> 0 | H30: =E30+F30-G30 -> 4 | I30: 2 | J30: =IF(H30<=I30,"CRITIQUE",IF(H30<=I30+1,"BAS","OK")) -> OK | K30: =IF(J30="CRITIQUE","A_REAPPROVISIONNER",IF(J30="BAS","SURVEILLER","OK")) -> OK | L30: N/A | M30: Vartra LongLife
A31: IT-133-0030 | C31: Piles AA | D31: 133 | E31: 5 | F31: =IFERROR(SUMIFS(MOUVEMENTS_STOCK!$E:$E,MOUVEMENTS_STOCK!$C:$C,A31,MOUVEMENTS_STOCK!$D:$D,"ENTREE"),0) -> 0 | G31: =IFERROR(SUMIFS(MOUVEMENTS_STOCK!$E:$E,MOUVEMENTS_STOCK!$C:$C,A31,MOUVEMENTS_STOCK!$D:$D,"SORTIE"),0) -> 0 | H31: =E31+F31-G31 -> 5 | I31: 2 | J31: =IF(H31<=I31,"CRITIQUE",IF(H31<=I31+1,"BAS","OK")) -> OK | K31: =IF(J31="CRITIQUE","A_REAPPROVISIONNER",IF(J31="BAS","SURVEILLER","OK")) -> OK | L31: N/A
A32: IT-133-0031 | C32: Piles AAA | D32: 133 | E32: 12 | F32: =IFERROR(SUMIFS(MOUVEMENTS_STOCK!$E:$E,MOUVEMENTS_STOCK!$C:$C,A32,MOUVEMENTS_STOCK!$D:$D,"ENTREE"),0) -> 0 | G32: =IFERROR(SUMIFS(MOUVEMENTS_STOCK!$E:$E,MOUVEMENTS_STOCK!$C:$C,A32,MOUVEMENTS_STOCK!$D:$D,"SORTIE"),0) -> 0 | H32: =E32+F32-G32 -> 12 | I32: 2 | J32: =IF(H32<=I32,"CRITIQUE",IF(H32<=I32+1,"BAS","OK")) -> OK | K32: =IF(J32="CRITIQUE","A_REAPPROVISIONNER",IF(J32="BAS","SURVEILLER","OK")) -> OK | L32: N/A
A33: IT-133-0032 | C33: Power | D33: 133 | E33: 0 | F33: =IFERROR(SUMIFS(MOUVEMENTS_STOCK!$E:$E,MOUVEMENTS_STOCK!$C:$C,A33,MOUVEMENTS_STOCK!$D:$D,"ENTREE"),0) -> 0 | G33: =IFERROR(SUMIFS(MOUVEMENTS_STOCK!$E:$E,MOUVEMENTS_STOCK!$C:$C,A33,MOUVEMENTS_STOCK!$D:$D,"SORTIE"),0) -> 0 | H33: =E33+F33-G33 -> 0 | I33: 1 | J33: =IF(H33<=I33,"CRITIQUE",IF(H33<=I33+1,"BAS","OK")) -> CRITIQUE | K33: =IF(J33="CRITIQUE","A_REAPPROVISIONNER",IF(J33="BAS","SURVEILLER","OK")) -> A_REAPPROVISIONNER | L33: N/A | M33: Court 1 à 2 mètres
A34: IT-133-0033 | C34: Souris | D34: 133 | E34: 5 | F34: =IFERROR(SUMIFS(MOUVEMENTS_STOCK!$E:$E,MOUVEMENTS_STOCK!$C:$C,A34,MOUVEMENTS_STOCK!$D:$D,"ENTREE"),0) -> 0 | G34: =IFERROR(SUMIFS(MOUVEMENTS_STOCK!$E:$E,MOUVEMENTS_STOCK!$C:$C,A34,MOUVEMENTS_STOCK!$D:$D,"SORTIE"),0) -> 0 | H34: =E34+F34-G34 -> 5 | I34: 2 | J34: =IF(H34<=I34,"CRITIQUE",IF(H34<=I34+1,"BAS","OK")) -> OK | K34: =IF(J34="CRITIQUE","A_REAPPROVISIONNER",IF(J34="BAS","SURVEILLER","OK")) -> OK | L34: N/A | M34: Old
A35: IT-133-0034 | C35: Switch Aruba | D35: 133 | E35: 10 | F35: =IFERROR(SUMIFS(MOUVEMENTS_STOCK!$E:$E,MOUVEMENTS_STOCK!$C:$C,A35,MOUVEMENTS_STOCK!$D:$D,"ENTREE"),0) -> 0 | G35: =IFERROR(SUMIFS(MOUVEMENTS_STOCK!$E:$E,MOUVEMENTS_STOCK!$C:$C,A35,MOUVEMENTS_STOCK!$D:$D,"SORTIE"),0) -> 0 | H35: =E35+F35-G35 -> 10 | I35: 2 | J35: =IF(H35<=I35,"CRITIQUE",IF(H35<=I35+1,"BAS","OK")) -> OK | K35: =IF(J35="CRITIQUE","A_REAPPROVISIONNER",IF(J35="BAS","SURVEILLER","OK")) -> OK | L35: CN36HKX0Z4_JL256 | M35: 48 Ports; PoE
A36: IT-133-0035 | C36: TV 32 Pousses | D36: 133 | E36: 10 | F36: =IFERROR(SUMIFS(MOUVEMENTS_STOCK!$E:$E,MOUVEMENTS_STOCK!$C:$C,A36,MOUVEMENTS_STOCK!$D:$D,"ENTREE"),0) -> 0 | G36: =IFERROR(SUMIFS(MOUVEMENTS_STOCK!$E:$E,MOUVEMENTS_STOCK!$C:$C,A36,MOUVEMENTS_STOCK!$D:$D,"SORTIE"),0) -> 0 | H36: =E36+F36-G36 -> 10 | I36: 2 | J36: =IF(H36<=I36,"CRITIQUE",IF(H36<=I36+1,"BAS","OK")) -> OK | K36: =IF(J36="CRITIQUE","A_REAPPROVISIONNER",IF(J36="BAS","SURVEILLER","OK")) -> OK | M36: TV en état de maintenance
A37: IT-133-0036 | C37: TV 40 pousse | D37: 133 | E37: 13 | F37: =IFERROR(SUMIFS(MOUVEMENTS_STOCK!$E:$E,MOUVEMENTS_STOCK!$C:$C,A37,MOUVEMENTS_STOCK!$D:$D,"ENTREE"),0) -> 0 | G37: =IFERROR(SUMIFS(MOUVEMENTS_STOCK!$E:$E,MOUVEMENTS_STOCK!$C:$C,A37,MOUVEMENTS_STOCK!$D:$D,"SORTIE"),0) -> 0 | H37: =E37+F37-G37 -> 13 | I37: 2 | J37: =IF(H37<=I37,"CRITIQUE",IF(H37<=I37+1,"BAS","OK")) -> OK | K37: =IF(J37="CRITIQUE","A_REAPPROVISIONNER",IF(J37="BAS","SURVEILLER","OK")) -> OK | M37: TV en état de maintenance
A38: IT-133-0037 | C38: TV 50 pousses | D38: 133 | E38: 0 | F38: =IFERROR(SUMIFS(MOUVEMENTS_STOCK!$E:$E,MOUVEMENTS_STOCK!$C:$C,A38,MOUVEMENTS_STOCK!$D:$D,"ENTREE"),0) -> 0 | G38: =IFERROR(SUMIFS(MOUVEMENTS_STOCK!$E:$E,MOUVEMENTS_STOCK!$C:$C,A38,MOUVEMENTS_STOCK!$D:$D,"SORTIE"),0) -> 0 | H38: =E38+F38-G38 -> 0 | I38: 1 | J38: =IF(H38<=I38,"CRITIQUE",IF(H38<=I38+1,"BAS","OK")) -> CRITIQUE | K38: =IF(J38="CRITIQUE","A_REAPPROVISIONNER",IF(J38="BAS","SURVEILLER","OK")) -> A_REAPPROVISIONNER
A39: IT-133-0038 | C39: TV 55 pousses | D39: 133 | E39: 6 | F39: =IFERROR(SUMIFS(MOUVEMENTS_STOCK!$E:$E,MOUVEMENTS_STOCK!$C:$C,A39,MOUVEMENTS_STOCK!$D:$D,"ENTREE"),0) -> 0 | G39: =IFERROR(SUMIFS(MOUVEMENTS_STOCK!$E:$E,MOUVEMENTS_STOCK!$C:$C,A39,MOUVEMENTS_STOCK!$D:$D,"SORTIE"),0) -> 0 | H39: =E39+F39-G39 -> 6 | I39: 2 | J39: =IF(H39<=I39,"CRITIQUE",IF(H39<=I39+1,"BAS","OK")) -> OK | K39: =IF(J39="CRITIQUE","A_REAPPROVISIONNER",IF(J39="BAS","SURVEILLER","OK")) -> OK | M39: Old TV
A40: IT-133-0039 | C40: TV 65 pousses | D40: 133 | E40: 2 | F40: =IFERROR(SUMIFS(MOUVEMENTS_STOCK!$E:$E,MOUVEMENTS_STOCK!$C:$C,A40,MOUVEMENTS_STOCK!$D:$D,"ENTREE"),0) -> 0 | G40: =IFERROR(SUMIFS(MOUVEMENTS_STOCK!$E:$E,MOUVEMENTS_STOCK!$C:$C,A40,MOUVEMENTS_STOCK!$D:$D,"SORTIE"),0) -> 0 | H40: =E40+F40-G40 -> 2 | I40: 2 | J40: =IF(H40<=I40,"CRITIQUE",IF(H40<=I40+1,"BAS","OK")) -> CRITIQUE | K40: =IF(J40="CRITIQUE","A_REAPPROVISIONNER",IF(J40="BAS","SURVEILLER","OK")) -> A_REAPPROVISIONNER | M40: New TV
...

Sheet MOUVEMENTS_STOCK
A1: Date | B1: Référence | C1: ID_Materiel | D1: Action | E1: Quantité | F1: Motif | G1: Responsable | H1: Commentaire
A2: 46013 | B2: REF-0001 | C2: IT-122-0001 | D2: ENTREE | E2: 1 | F2: Achat | H2: Exemple (supprimer)

Sheet ATTRIBUTIONS
A1: Date | B1: ID_Materiel | C1: Employé | D1: Département | E1: Localisation | F1: État | G1: Date_Retour_Prévue | H1: Commentaire

Sheet ALERTES
A1: Alertes stock (auto)

Sheet DASHBOARD
A1: Tableau de bord — Stock IT
A3: Total références | B3: =COUNTA(INVENTAIRE!A2:A78) -> 77
A4: Références en stock critique | B4: =COUNTIF(INVENTAIRE!J2:J78,"CRITIQUE") -> 35
A5: Références en stock bas | B5: =COUNTIF(INVENTAIRE!J2:J78,"BAS") -> 7
A6: Références OK | B6: =COUNTIF(INVENTAIRE!J2:J78,"OK") -> 35

Sheet PARAMETRES
A1: Listes (ne pas supprimer)
A2: Statuts | B2: Actions | C2: Motifs | D2: Categories | E2: Localisations
A3: OK | B3: ENTREE | C3: Achat | D3: Périphérique | E3: 122
A4: HS | B4: SORTIE | C4: Transfert | D4: Réseau | E4: 133
A5: EN_REPARATION | B5: AJUSTEMENT | C5: Attribution | D5: Serveur | E5: Bureau IT
A6: PERDU | C6: Retour | D6: Téléphonie | E6: Sono
A7: REBUT | C7: Panne | D7: Impression | E7: Radisson Blu
C8: Perte | D8: Stockage | E8: Park Inn
C9: Inventaire | D9: Câblage | E9: Bureau IT
C10: Autre | D10: Autre

Sheet GUIDE
A1: Guide d’utilisation (Radisson IT Dept)
A3: 1) Ajoute/retire du stock uniquement via la feuille MOUVEMENTS_STOCK.
A4: - Action ENTREE : Quantité positive
A5: - Action SORTIE : Quantité positive (sera soustraite automatiquement)
A6: 2) Ne modifie pas les formules dans INVENTAIRE (colonnes Entrées/Sorties/Stock_Actuel/Alerte).
A7: 3) Complète Stock_Min par référence pour activer des alertes pertinentes.
A8: 4) Utilise ATTRIBUTIONS pour tracer qui possède quel matériel (prêts/attributions).
A9: 5) La feuille ALERTES se met à jour automatiquement (Excel 365 recommandé).
A10: 6) Migration Django : export CSV de INVENTAIRE + MOUVEMENTS_STOCK + ATTRIBUTIONS.
